2018-04-11 14:58:26,939 INFO: Microblog startup [in /Users/jizhoutang/microBlog/app/__init__.py:76]
2018-04-11 14:59:30,434 INFO: Microblog startup [in /Users/jizhoutang/microBlog/app/__init__.py:76]
2018-04-11 15:45:57,020 INFO: Microblog startup [in /Users/jizhoutang/microBlog/app/__init__.py:76]
2018-04-11 15:46:11,455 ERROR: Exception on /search [GET] [in /Users/jizhoutang/microBlog/microBlogEnv/lib/python3.6/site-packages/flask/app.py:1560]
Traceback (most recent call last):
  File "/Users/jizhoutang/microBlog/microBlogEnv/lib/python3.6/site-packages/urllib3/connection.py", line 141, in _new_conn
    (self.host, self.port), self.timeout, **extra_kw)
  File "/Users/jizhoutang/microBlog/microBlogEnv/lib/python3.6/site-packages/urllib3/util/connection.py", line 83, in create_connection
    raise err
  File "/Users/jizhoutang/microBlog/microBlogEnv/lib/python3.6/site-packages/urllib3/util/connection.py", line 73, in create_connection
    sock.connect(sa)
ConnectionRefusedError: [Errno 61] Connection refused

During handling of the above exception, another exception occurred:

Traceback (most recent call last):
  File "/Users/jizhoutang/microBlog/microBlogEnv/lib/python3.6/site-packages/elasticsearch/connection/http_urllib3.py", line 166, in perform_request
    response = self.pool.urlopen(method, url, body, retries=False, headers=request_headers, **kw)
  File "/Users/jizhoutang/microBlog/microBlogEnv/lib/python3.6/site-packages/urllib3/connectionpool.py", line 639, in urlopen
    _stacktrace=sys.exc_info()[2])
  File "/Users/jizhoutang/microBlog/microBlogEnv/lib/python3.6/site-packages/urllib3/util/retry.py", line 333, in increment
    raise six.reraise(type(error), error, _stacktrace)
  File "/Users/jizhoutang/microBlog/microBlogEnv/lib/python3.6/site-packages/urllib3/packages/six.py", line 686, in reraise
    raise value
  File "/Users/jizhoutang/microBlog/microBlogEnv/lib/python3.6/site-packages/urllib3/connectionpool.py", line 601, in urlopen
    chunked=chunked)
  File "/Users/jizhoutang/microBlog/microBlogEnv/lib/python3.6/site-packages/urllib3/connectionpool.py", line 357, in _make_request
    conn.request(method, url, **httplib_request_kw)
  File "/Users/jizhoutang/anaconda3/lib/python3.6/http/client.py", line 1239, in request
    self._send_request(method, url, body, headers, encode_chunked)
  File "/Users/jizhoutang/anaconda3/lib/python3.6/http/client.py", line 1285, in _send_request
    self.endheaders(body, encode_chunked=encode_chunked)
  File "/Users/jizhoutang/anaconda3/lib/python3.6/http/client.py", line 1234, in endheaders
    self._send_output(message_body, encode_chunked=encode_chunked)
  File "/Users/jizhoutang/anaconda3/lib/python3.6/http/client.py", line 1026, in _send_output
    self.send(msg)
  File "/Users/jizhoutang/anaconda3/lib/python3.6/http/client.py", line 964, in send
    self.connect()
  File "/Users/jizhoutang/microBlog/microBlogEnv/lib/python3.6/site-packages/urllib3/connection.py", line 166, in connect
    conn = self._new_conn()
  File "/Users/jizhoutang/microBlog/microBlogEnv/lib/python3.6/site-packages/urllib3/connection.py", line 150, in _new_conn
    self, "Failed to establish a new connection: %s" % e)
urllib3.exceptions.NewConnectionError: <urllib3.connection.HTTPConnection object at 0x10930f2b0>: Failed to establish a new connection: [Errno 61] Connection refused

During handling of the above exception, another exception occurred:

Traceback (most recent call last):
  File "/Users/jizhoutang/microBlog/microBlogEnv/lib/python3.6/site-packages/flask/app.py", line 1982, in wsgi_app
    response = self.full_dispatch_request()
  File "/Users/jizhoutang/microBlog/microBlogEnv/lib/python3.6/site-packages/flask/app.py", line 1614, in full_dispatch_request
    rv = self.handle_user_exception(e)
  File "/Users/jizhoutang/microBlog/microBlogEnv/lib/python3.6/site-packages/flask/app.py", line 1517, in handle_user_exception
    reraise(exc_type, exc_value, tb)
  File "/Users/jizhoutang/microBlog/microBlogEnv/lib/python3.6/site-packages/flask/_compat.py", line 33, in reraise
    raise value
  File "/Users/jizhoutang/microBlog/microBlogEnv/lib/python3.6/site-packages/flask/app.py", line 1612, in full_dispatch_request
    rv = self.dispatch_request()
  File "/Users/jizhoutang/microBlog/microBlogEnv/lib/python3.6/site-packages/flask/app.py", line 1598, in dispatch_request
    return self.view_functions[rule.endpoint](**req.view_args)
  File "/Users/jizhoutang/microBlog/microBlogEnv/lib/python3.6/site-packages/flask_login/utils.py", line 261, in decorated_view
    return func(*args, **kwargs)
  File "/Users/jizhoutang/microBlog/app/main/routes.py", line 126, in search
    posts, total = Post.search(g.search_form.q.data, page, current_app.config['POSTS_PER_PAGE'])
  File "/Users/jizhoutang/microBlog/app/models.py", line 78, in search
    ids, total = query_index(cls.__tablename__, expression, page, per_page)
  File "/Users/jizhoutang/microBlog/app/search.py", line 23, in query_index
    'from': (page-1)*per_page, 'size': per_page
  File "/Users/jizhoutang/microBlog/microBlogEnv/lib/python3.6/site-packages/elasticsearch/client/utils.py", line 76, in _wrapped
    return func(*args, params=params, **kwargs)
  File "/Users/jizhoutang/microBlog/microBlogEnv/lib/python3.6/site-packages/elasticsearch/client/__init__.py", line 655, in search
    doc_type, '_search'), params=params, body=body)
  File "/Users/jizhoutang/microBlog/microBlogEnv/lib/python3.6/site-packages/elasticsearch/transport.py", line 314, in perform_request
    status, headers_response, data = connection.perform_request(method, url, params, body, headers=headers, ignore=ignore, timeout=timeout)
  File "/Users/jizhoutang/microBlog/microBlogEnv/lib/python3.6/site-packages/elasticsearch/connection/http_urllib3.py", line 175, in perform_request
    raise ConnectionError('N/A', str(e), e)
elasticsearch.exceptions.ConnectionError: ConnectionError(<urllib3.connection.HTTPConnection object at 0x10930f2b0>: Failed to establish a new connection: [Errno 61] Connection refused) caused by: NewConnectionError(<urllib3.connection.HTTPConnection object at 0x10930f2b0>: Failed to establish a new connection: [Errno 61] Connection refused)
